Yes, you can nest a try block inside another try block. This is called nested exception handling